[2025-10-30 15:11:21 UTC] üöÄ Daemon started.
[2025-10-30 15:11:22 UTC] ‚ùå Exception: KeyError('ma_fast')
[2025-10-30 15:11:22 UTC] Traceback (most recent call last):
  File "/Users/chuan/Documents/Projects/OANDA_AutoTrader/.venv/lib/python3.13/site-packages/pandas/core/indexes/base.py", line 3812, in get_loc
    return self._engine.get_loc(casted_key)
           ~~~~~~~~~~~~~~~~~~~~^^^^^^^^^^^^
  File "pandas/_libs/index.pyx", line 167, in pandas._libs.index.IndexEngine.get_loc
  File "pandas/_libs/index.pyx", line 196, in pandas._libs.index.IndexEngine.get_loc
  File "pandas/_libs/hashtable_class_helper.pxi", line 7088, in pandas._libs.hashtable.PyObjectHashTable.get_item
  File "pandas/_libs/hashtable_class_helper.pxi", line 7096, in pandas._libs.hashtable.PyObjectHashTable.get_item
KeyError: 'ma_fast'

The above exception was the direct cause of the following exception:

Traceback (most recent call last):
  File "/Users/chuan/Documents/Projects/OANDA_AutoTrader/mian_loop.py", line 104, in main_loop
    last_done_time = run_once(api, last_done_time)
  File "/Users/chuan/Documents/Projects/OANDA_AutoTrader/mian_loop.py", line 52, in run_once
    last_maf, last_mas = last["ma_fast"], last["ma_slow"]
                         ~~~~^^^^^^^^^^^
  File "/Users/chuan/Documents/Projects/OANDA_AutoTrader/.venv/lib/python3.13/site-packages/pandas/core/series.py", line 1133, in __getitem__
    return self._get_value(key)
           ~~~~~~~~~~~~~~~^^^^^
  File "/Users/chuan/Documents/Projects/OANDA_AutoTrader/.venv/lib/python3.13/site-packages/pandas/core/series.py", line 1249, in _get_value
    loc = self.index.get_loc(label)
  File "/Users/chuan/Documents/Projects/OANDA_AutoTrader/.venv/lib/python3.13/site-packages/pandas/core/indexes/base.py", line 3819, in get_loc
    raise KeyError(key) from err
KeyError: 'ma_fast'

[2025-10-30 15:12:22 UTC] ‚ùå Exception: KeyError('ma_fast')
[2025-10-30 15:12:22 UTC] Traceback (most recent call last):
  File "/Users/chuan/Documents/Projects/OANDA_AutoTrader/.venv/lib/python3.13/site-packages/pandas/core/indexes/base.py", line 3812, in get_loc
    return self._engine.get_loc(casted_key)
           ~~~~~~~~~~~~~~~~~~~~^^^^^^^^^^^^
  File "pandas/_libs/index.pyx", line 167, in pandas._libs.index.IndexEngine.get_loc
  File "pandas/_libs/index.pyx", line 196, in pandas._libs.index.IndexEngine.get_loc
  File "pandas/_libs/hashtable_class_helper.pxi", line 7088, in pandas._libs.hashtable.PyObjectHashTable.get_item
  File "pandas/_libs/hashtable_class_helper.pxi", line 7096, in pandas._libs.hashtable.PyObjectHashTable.get_item
KeyError: 'ma_fast'

The above exception was the direct cause of the following exception:

Traceback (most recent call last):
  File "/Users/chuan/Documents/Projects/OANDA_AutoTrader/mian_loop.py", line 104, in main_loop
    last_done_time = run_once(api, last_done_time)
  File "/Users/chuan/Documents/Projects/OANDA_AutoTrader/mian_loop.py", line 52, in run_once
    last_maf, last_mas = last["ma_fast"], last["ma_slow"]
                         ~~~~^^^^^^^^^^^
  File "/Users/chuan/Documents/Projects/OANDA_AutoTrader/.venv/lib/python3.13/site-packages/pandas/core/series.py", line 1133, in __getitem__
    return self._get_value(key)
           ~~~~~~~~~~~~~~~^^^^^
  File "/Users/chuan/Documents/Projects/OANDA_AutoTrader/.venv/lib/python3.13/site-packages/pandas/core/series.py", line 1249, in _get_value
    loc = self.index.get_loc(label)
  File "/Users/chuan/Documents/Projects/OANDA_AutoTrader/.venv/lib/python3.13/site-packages/pandas/core/indexes/base.py", line 3819, in get_loc
    raise KeyError(key) from err
KeyError: 'ma_fast'

[2025-10-30 15:13:06 UTC] üöÄ Daemon started.
[2025-10-30 15:13:07 UTC] ‚ùå Exception: KeyError('ma_fast')
[2025-10-30 15:13:07 UTC] Traceback (most recent call last):
  File "/Users/chuan/Documents/Projects/OANDA_AutoTrader/.venv/lib/python3.13/site-packages/pandas/core/indexes/base.py", line 3812, in get_loc
    return self._engine.get_loc(casted_key)
           ~~~~~~~~~~~~~~~~~~~~^^^^^^^^^^^^
  File "pandas/_libs/index.pyx", line 167, in pandas._libs.index.IndexEngine.get_loc
  File "pandas/_libs/index.pyx", line 196, in pandas._libs.index.IndexEngine.get_loc
  File "pandas/_libs/hashtable_class_helper.pxi", line 7088, in pandas._libs.hashtable.PyObjectHashTable.get_item
  File "pandas/_libs/hashtable_class_helper.pxi", line 7096, in pandas._libs.hashtable.PyObjectHashTable.get_item
KeyError: 'ma_fast'

The above exception was the direct cause of the following exception:

Traceback (most recent call last):
  File "/Users/chuan/Documents/Projects/OANDA_AutoTrader/main_loop.py", line 104, in main_loop
    last_done_time = run_once(api, last_done_time)
  File "/Users/chuan/Documents/Projects/OANDA_AutoTrader/main_loop.py", line 52, in run_once
    last_maf, last_mas = last["ma_fast"], last["ma_slow"]
                         ~~~~^^^^^^^^^^^
  File "/Users/chuan/Documents/Projects/OANDA_AutoTrader/.venv/lib/python3.13/site-packages/pandas/core/series.py", line 1133, in __getitem__
    return self._get_value(key)
           ~~~~~~~~~~~~~~~^^^^^
  File "/Users/chuan/Documents/Projects/OANDA_AutoTrader/.venv/lib/python3.13/site-packages/pandas/core/series.py", line 1249, in _get_value
    loc = self.index.get_loc(label)
  File "/Users/chuan/Documents/Projects/OANDA_AutoTrader/.venv/lib/python3.13/site-packages/pandas/core/indexes/base.py", line 3819, in get_loc
    raise KeyError(key) from err
KeyError: 'ma_fast'

[2025-10-30 15:14:07 UTC] ‚ùå Exception: KeyError('ma_fast')
[2025-10-30 15:14:07 UTC] Traceback (most recent call last):
  File "/Users/chuan/Documents/Projects/OANDA_AutoTrader/.venv/lib/python3.13/site-packages/pandas/core/indexes/base.py", line 3812, in get_loc
    return self._engine.get_loc(casted_key)
           ~~~~~~~~~~~~~~~~~~~~^^^^^^^^^^^^
  File "pandas/_libs/index.pyx", line 167, in pandas._libs.index.IndexEngine.get_loc
  File "pandas/_libs/index.pyx", line 196, in pandas._libs.index.IndexEngine.get_loc
  File "pandas/_libs/hashtable_class_helper.pxi", line 7088, in pandas._libs.hashtable.PyObjectHashTable.get_item
  File "pandas/_libs/hashtable_class_helper.pxi", line 7096, in pandas._libs.hashtable.PyObjectHashTable.get_item
KeyError: 'ma_fast'

The above exception was the direct cause of the following exception:

Traceback (most recent call last):
  File "/Users/chuan/Documents/Projects/OANDA_AutoTrader/main_loop.py", line 104, in main_loop
    last_done_time = run_once(api, last_done_time)
  File "/Users/chuan/Documents/Projects/OANDA_AutoTrader/main_loop.py", line 52, in run_once
    last_maf, last_mas = last["ma_fast"], last["ma_slow"]
                         ~~~~^^^^^^^^^^^
  File "/Users/chuan/Documents/Projects/OANDA_AutoTrader/.venv/lib/python3.13/site-packages/pandas/core/series.py", line 1133, in __getitem__
    return self._get_value(key)
           ~~~~~~~~~~~~~~~^^^^^
  File "/Users/chuan/Documents/Projects/OANDA_AutoTrader/.venv/lib/python3.13/site-packages/pandas/core/series.py", line 1249, in _get_value
    loc = self.index.get_loc(label)
  File "/Users/chuan/Documents/Projects/OANDA_AutoTrader/.venv/lib/python3.13/site-packages/pandas/core/indexes/base.py", line 3819, in get_loc
    raise KeyError(key) from err
KeyError: 'ma_fast'

[2025-10-30 15:15:07 UTC] ‚ùå Exception: KeyError('ma_fast')
[2025-10-30 15:15:07 UTC] Traceback (most recent call last):
  File "/Users/chuan/Documents/Projects/OANDA_AutoTrader/.venv/lib/python3.13/site-packages/pandas/core/indexes/base.py", line 3812, in get_loc
    return self._engine.get_loc(casted_key)
           ~~~~~~~~~~~~~~~~~~~~^^^^^^^^^^^^
  File "pandas/_libs/index.pyx", line 167, in pandas._libs.index.IndexEngine.get_loc
  File "pandas/_libs/index.pyx", line 196, in pandas._libs.index.IndexEngine.get_loc
  File "pandas/_libs/hashtable_class_helper.pxi", line 7088, in pandas._libs.hashtable.PyObjectHashTable.get_item
  File "pandas/_libs/hashtable_class_helper.pxi", line 7096, in pandas._libs.hashtable.PyObjectHashTable.get_item
KeyError: 'ma_fast'

The above exception was the direct cause of the following exception:

Traceback (most recent call last):
  File "/Users/chuan/Documents/Projects/OANDA_AutoTrader/main_loop.py", line 104, in main_loop
    last_done_time = run_once(api, last_done_time)
  File "/Users/chuan/Documents/Projects/OANDA_AutoTrader/main_loop.py", line 52, in run_once
    last_maf, last_mas = last["ma_fast"], last["ma_slow"]
                         ~~~~^^^^^^^^^^^
  File "/Users/chuan/Documents/Projects/OANDA_AutoTrader/.venv/lib/python3.13/site-packages/pandas/core/series.py", line 1133, in __getitem__
    return self._get_value(key)
           ~~~~~~~~~~~~~~~^^^^^
  File "/Users/chuan/Documents/Projects/OANDA_AutoTrader/.venv/lib/python3.13/site-packages/pandas/core/series.py", line 1249, in _get_value
    loc = self.index.get_loc(label)
  File "/Users/chuan/Documents/Projects/OANDA_AutoTrader/.venv/lib/python3.13/site-packages/pandas/core/indexes/base.py", line 3819, in get_loc
    raise KeyError(key) from err
KeyError: 'ma_fast'

[2025-10-30 15:16:08 UTC] ‚ùå Exception: KeyError('ma_fast')
[2025-10-30 15:16:08 UTC] Traceback (most recent call last):
  File "/Users/chuan/Documents/Projects/OANDA_AutoTrader/.venv/lib/python3.13/site-packages/pandas/core/indexes/base.py", line 3812, in get_loc
    return self._engine.get_loc(casted_key)
           ~~~~~~~~~~~~~~~~~~~~^^^^^^^^^^^^
  File "pandas/_libs/index.pyx", line 167, in pandas._libs.index.IndexEngine.get_loc
  File "pandas/_libs/index.pyx", line 196, in pandas._libs.index.IndexEngine.get_loc
  File "pandas/_libs/hashtable_class_helper.pxi", line 7088, in pandas._libs.hashtable.PyObjectHashTable.get_item
  File "pandas/_libs/hashtable_class_helper.pxi", line 7096, in pandas._libs.hashtable.PyObjectHashTable.get_item
KeyError: 'ma_fast'

The above exception was the direct cause of the following exception:

Traceback (most recent call last):
  File "/Users/chuan/Documents/Projects/OANDA_AutoTrader/main_loop.py", line 104, in main_loop
    api = OandaAPI(ACCESS_TOKEN, ACCOUNT_ID, environment=ENVIRONMENT)
                             ^^^^^^^^^^^^^^^^^^^^^^^^^^^^^
  File "/Users/chuan/Documents/Projects/OANDA_AutoTrader/main_loop.py", line 52, in run_once
    last = done.iloc[-1]
    
  File "/Users/chuan/Documents/Projects/OANDA_AutoTrader/.venv/lib/python3.13/site-packages/pandas/core/series.py", line 1133, in __getitem__
    return self._get_value(key)
           ~~~~~~~~~~~~~~~^^^^^
  File "/Users/chuan/Documents/Projects/OANDA_AutoTrader/.venv/lib/python3.13/site-packages/pandas/core/series.py", line 1249, in _get_value
    loc = self.index.get_loc(label)
  File "/Users/chuan/Documents/Projects/OANDA_AutoTrader/.venv/lib/python3.13/site-packages/pandas/core/indexes/base.py", line 3819, in get_loc
    raise KeyError(key) from err
KeyError: 'ma_fast'

[2025-10-30 15:16:36 UTC] üöÄ Daemon started.
[2025-10-30 15:16:37 UTC] ‚ÑπÔ∏è Êó†‰ø°Âè∑ÔºàÊñ∞KÁ∫øÂ∑≤ÂÆåÊàêÔºâ„ÄÇ
[2025-10-30 15:16:37 UTC] ‚ùå Exception: NameError("name 'last_time' is not defined")
[2025-10-30 15:16:37 UTC] Traceback (most recent call last):
  File "/Users/chuan/Documents/Projects/OANDA_AutoTrader/main_loop.py", line 110, in main_loop
    last_done_time = run_once(api, last_done_time)
  File "/Users/chuan/Documents/Projects/OANDA_AutoTrader/main_loop.py", line 101, in run_once
    return last_time
           ^^^^^^^^^
NameError: name 'last_time' is not defined

[2025-10-30 15:17:37 UTC] ‚ÑπÔ∏è Êó†‰ø°Âè∑ÔºàÊñ∞KÁ∫øÂ∑≤ÂÆåÊàêÔºâ„ÄÇ
[2025-10-30 15:17:37 UTC] ‚ùå Exception: NameError("name 'last_time' is not defined")
[2025-10-30 15:17:37 UTC] Traceback (most recent call last):
  File "/Users/chuan/Documents/Projects/OANDA_AutoTrader/main_loop.py", line 110, in main_loop
    last_done_time = run_once(api, last_done_time)
  File "/Users/chuan/Documents/Projects/OANDA_AutoTrader/main_loop.py", line 101, in run_once
    return last_time
           ^^^^^^^^^
NameError: name 'last_time' is not defined

[2025-10-30 15:17:58 UTC] üöÄ Daemon started.
[2025-10-30 15:17:59 UTC] ‚ÑπÔ∏è Êó†‰ø°Âè∑ÔºàÊñ∞KÁ∫øÂ∑≤ÂÆåÊàêÔºâ„ÄÇ
[2025-10-30 15:18:59 UTC] ‚è≥ No new closed candle. LastDone=2025-10-30 15:10:00+00:00
[2025-10-30 15:20:00 UTC] ‚ÑπÔ∏è Êó†‰ø°Âè∑ÔºàÊñ∞KÁ∫øÂ∑≤ÂÆåÊàêÔºâ„ÄÇ
[2025-10-30 15:21:00 UTC] ‚è≥ No new closed candle. LastDone=2025-10-30 15:15:00+00:00
[2025-10-30 15:22:00 UTC] ‚è≥ No new closed candle. LastDone=2025-10-30 15:15:00+00:00
